Workbook

Sheet Sheet2
A3: Row Labels | B3: Sum of TOTAL PRICE
A4: - 1000A - Al - update MTO - rev 00.xlsx | B4: 3.1790186e+09
A5: - 1250A - Al - update MTO - rev 00.xlsx | B5: 3.7676625e+09
A6: - 1600A - Al - update MTO - rev 00.xlsx | B6: 5.6340843e+09
A7: - 2000A - Al - update MTO - rev 00.xlsx | B7: 4.9407238e+09
A8: - 2500A - Al - update MTO - rev 00.xlsx | B8: 6.2849022e+09
A9: - 3200A - Al - update MTO - rev 00.xlsx | B9: 7.0711405e+09
A10: - 400A -630A - Al - update MTO - rev 00.xlsx | B10: 2.6299189e+09
A11: - 800A - Al - update MTO - rev 00.xlsx | B11: 2.8738288e+09
A12: - 4000A - Al - update MTO - rev 00.xlsx | B12: 8.45009e+09
A13: - 5000A - Al - update MTO - rev 00.xlsx | B13: 9.9675082e+09
A14: Grand Total | B14: 5.4798878e+10

Sheet Al update MTO - 05-1-30
A1: Source.Name | B1: Name | C1: ردیف | D1: دسته | E1: متریال | F1: DIMENTION | G1: QTY | H1: VALUE | I1: UNIT | J1: UNIT PRICE | K1: TOTAL PRICE | L1: Item | M1: Kind | N1: Hidden
A2: - 1000A - Al - update MTO - rev 00.xlsx | B2: FEEDER-1000 | C2: 1 | D2: آلومینیوم | E2: پروفیل یو شکل | F2: 2735 | G2: 2 | H2: 7.658 | I2: Kg | J2: 8500000 | K2: 65093000 | L2: FEEDER-1000 | M2: Sheet | N2: FALSE
A3: - 1000A - Al - update MTO - rev 00.xlsx | B3: FEEDER-1000 | C3: 2 | E3: پروفیل آی شکل | F3: 2735 | G3: 0 | H3: 0 | I3: Kg | J3: 8500000 | K3: 0 | L3: FEEDER-1000 | M3: Sheet | N3: FALSE
A4: - 1000A - Al - update MTO - rev 00.xlsx | B4: FEEDER-1000 | C4: 3 | E4: هیت سینگ 163 | F4: 2703 | G4: 2 | H4: 9.1902 | I4: Kg | J4: 8500000 | K4: 78116700 | L4: FEEDER-1000 | M4: Sheet | N4: FALSE
A5: - 1000A - Al - update MTO - rev 00.xlsx | B5: FEEDER-1000 | C5: 4 | E5: دایکاست (نگهدارنده کاور) | F5: 120 | G5: 4 | H5: 0.48 | I5: Kg | J5: 8500000 | K5: 4080000 | L5: FEEDER-1000 | M5: Sheet | N5: FALSE
A6: - 1000A - Al - update MTO - rev 00.xlsx | B6: FEEDER-1000 | C6: 5 | E6: گارد | F6: 180 | G6: 4 | H6: 0.950616 | I6: Kg | J6: 8500000 | K6: 8080236 | L6: FEEDER-1000 | M6: Sheet | N6: FALSE
A7: - 1000A - Al - update MTO - rev 00.xlsx | B7: FEEDER-1000 | C7: 6 | E7: شینه آلومینیوم 6 میلیمتری | F7: 2970 | G7: 4 | H7: 19.2456 | I7: Kg | J7: 8500000 | K7: 1.635876e+08 | L7: FEEDER-1000 | M7: Sheet | N7: FALSE
A8: - 1000A - Al - update MTO - rev 00.xlsx | B8: FEEDER-1000 | C8: 7 | D8: عایق ها | E8: عایق میکا | F8: 0.13 | G8: 2.75616 | H8: 2.75616 | I8: M2 | J8: 4275000 | K8: 11782584 | L8: FEEDER-1000 | M8: Sheet | N8: FALSE
A9: - 1000A - Al - update MTO - rev 00.xlsx | B9: FEEDER-1000 | C9: 8 | E9: عایق نومکس یا مایلار | F9: 0.35 | G9: 1.2127104 | H9: 1.2127104 | I9: Kg | J9: 35750000 | K9: 43354397 | L9: FEEDER-1000 | M9: Sheet | N9: FALSE
A10: - 1000A - Al - update MTO - rev 00.xlsx | B10: FEEDER-1000 | C10: 9 | E10: عایق نومکس یا مایلار | F10: 0.2 | G10: 0 | H10: 0 | I10: Kg | J10: 45760000 | K10: 0 | L10: FEEDER-1000 | M10: Sheet | N10: FALSE
A11: - 1000A - Al - update MTO - rev 00.xlsx | B11: FEEDER-1000 | C11: 10 | D11: رنگ بدنه | E11: رنگ پودری | G11: 16.8482 | H11: 16.8482 | I11: Kg | J11: 1430000 | K11: 24092926 | L11: FEEDER-1000 | M11: Sheet | N11: FALSE
A12: - 1000A - Al - update MTO - rev 00.xlsx | B12: FEEDER-1000 | C12: 11 | D12: قلع | E12: ابکاری پلیت | G12: 8 | H12: 8 | I12: Kg | J12: 1600000 | K12: 12800000 | L12: FEEDER-1000 | M12: Sheet | N12: FALSE
A13: - 1000A - Al - update MTO - rev 00.xlsx | B13: FEEDER-1000 | C13: 12 | E13: ابکاری شینه ها سراسر | G13: 19.2456 | H13: 19.2456 | I13: PCS | J13: 3600000 | K13: 69284160 | L13: FEEDER-1000 | M13: Sheet | N13: FALSE
A14: - 1000A - Al - update MTO - rev 00.xlsx | B14: FEEDER-1000 | C14: 13 | D14: چسب | E14: چسب عایق ها | G14: 11.88 | H14: 11.88 | I14: PCS | J14: 3600000 | K14: 42768000 | L14: FEEDER-1000 | M14: Sheet | N14: FALSE
A15: - 1000A - Al - update MTO - rev 00.xlsx | B15: FEEDER-1000 | C15: 14 | E15: چسب سیلیکون | G15: 0.1 | H15: 0.1 | I15: PCS | J15: 5500000 | K15: 550000 | L15: FEEDER-1000 | M15: Sheet | N15: FALSE
A16: - 1000A - Al - update MTO - rev 00.xlsx | B16: FEEDER-1000 | C16: 15 | D16: پیچ و مهره | E16: پیچ 8x20 | G16: 80 | H16: 80 | I16: PCS | J16: 200000 | K16: 16000000 | L16: FEEDER-1000 | M16: Sheet | N16: FALSE
A17: - 1000A - Al - update MTO - rev 00.xlsx | B17: FEEDER-1000 | C17: 16 | E17: پیچ 8x25 | G17: 8 | H17: 8 | I17: PCS | J17: 200000 | K17: 1600000 | L17: FEEDER-1000 | M17: Sheet | N17: FALSE
A18: - 1000A - Al - update MTO - rev 00.xlsx | B18: FEEDER-1000 | C18: 17 | E18: مهره خاردار 8 | G18: 88 | H18: 88 | I18: PCS | J18: 200000 | K18: 17600000 | L18: FEEDER-1000 | M18: Sheet | N18: FALSE
A19: - 1000A - Al - update MTO - rev 00.xlsx | B19: FEEDER-1000 | C19: 18 | E19: پیچ 6x10 | G19: 16 | H19: 16 | I19: PCS | J19: 400000 | K19: 6400000 | L19: FEEDER-1000 | M19: Sheet | N19: FALSE
A20: - 1000A - Al - update MTO - rev 00.xlsx | B20: FEEDER-1000 | C20: 19 | E20: مهره پرچی ته بسته 6 | G20: 16 | H20: 16 | I20: PCS | J20: 120000 | K20: 1920000 | L20: FEEDER-1000 | M20: Sheet | N20: FALSE
A21: - 1000A - Al - update MTO - rev 00.xlsx | B21: FEEDER-1000 | C21: 20 | E21: پیچ 6x15 | G21: 24 | H21: 24 | I21: PCS | J21: 400000 | K21: 9600000 | L21: FEEDER-1000 | M21: Sheet | N21: FALSE
A22: - 1000A - Al - update MTO - rev 00.xlsx | B22: FEEDER-1000 | C22: 21 | D22: مس | E22: پلیت مونو بلاک | F22: 132 | G22: 8 | H22: 2.838528 | I22: Kg | J22: 35000000 | K22: 99348480 | L22: FEEDER-1000 | M22: Sheet | N22: FALSE
A23: - 1000A - Al - update MTO - rev 00.xlsx | B23: FEEDER-1000 | C23: 22 | D23: آهن | E23: کاورهای کناری | F23: 115 X 185 | G23: 2 | H23: 1 | I23: Kg | J23: 5200000 | K23: 5200000 | L23: FEEDER-1000 | M23: Sheet | N23: FALSE
A24: - 1000A - Al - update MTO - rev 00.xlsx | B24: FEEDER-1000 | C24: 23 | E24: کاور بالا و پایین | F24: 425 X 265 | G24: 2 | H24: 1.2 | I24: Kg | J24: 5200000 | K24: 6240000 | L24: FEEDER-1000 | M24: Sheet | N24: FALSE
A25: - 1000A - Al - update MTO - rev 00.xlsx | B25: FEEDER-1000 | C25: 24 | D25: الومینیوم | E25: هولدر مونوبلاک | F25: 163*157 | G25: 2 | H25: 0.575879 | I25: Kg | J25: 8500000 | K25: 4894971.5 | L25: FEEDER-1000 | M25: Sheet | N25: FALSE
A26: - 1000A - Al - update MTO - rev 00.xlsx | B26: FEEDER-1000 | C26: 25 | D26: پلی امید | E26: عایق یک طرفه | F26: 0.18 | G26: 2 | H26: 2 | I26: PCS | J26: 715000 | K26: 1430000 | L26: FEEDER-1000 | M26: Sheet | N26: FALSE
A27: - 1000A - Al - update MTO - rev 00.xlsx | B27: FEEDER-1000 | C27: 26 | E27: عایق دو طرفه | F27: 0.2 | G27: 3 | H27: 3 | I27: PCS | J27: 715000 | K27: 2145000 | L27: FEEDER-1000 | M27: Sheet | N27: FALSE
A28: - 1000A - Al - update MTO - rev 00.xlsx | B28: FEEDER-1000 | C28: 27 | D28: ABS | E28: قطعه شش ضلعی | F28: 80 mm | G28: 1 | H28: 1 | I28: PCS | J28: 100000 | K28: 100000 | L28: FEEDER-1000 | M28: Sheet | N28: FALSE
A29: - 1000A - Al - update MTO - rev 00.xlsx | B29: FEEDER-1000 | C29: 28 | D29: پیچ و مهره | E29: پیچ 12x120 | G29: 2 | H29: 2 | I29: PCS | J29: 2400000 | K29: 4800000 | L29: FEEDER-1000 | M29: Sheet | N29: FALSE
A30: - 1000A - Al - update MTO - rev 00.xlsx | B30: FEEDER-1000 | C30: 29 | E30: مهره مربعی | G30: 2 | H30: 2 | I30: PCS | J30: 2400000 | K30: 4800000 | L30: FEEDER-1000 | M30: Sheet | N30: FALSE
A31: - 1000A - Al - update MTO - rev 00.xlsx | B31: FEEDER-1000 | C31: 30 | E31: واشر قابلمه ای 74 به ضخامت 5 میلیمتر | G31: 2 | H31: 2 | I31: PCS | J31: 3000000 | K31: 6000000 | L31: FEEDER-1000 | M31: Sheet | N31: FALSE
A32: - 1000A - Al - update MTO - rev 00.xlsx | B32: FEEDER-1000 | C32: 31 | D32: نوار IP | E32: نوار چسبی مونوبلاک ها | G32: 2 | H32: 2 | I32: PCS | J32: 1300000 | K32: 2600000 | L32: FEEDER-1000 | M32: Sheet | N32: FALSE
A33: - 1000A - Al - update MTO - rev 00.xlsx | B33: FEEDER-1000 | C33: 32 | D33: نوار IP | E33: نوار آی پی 25 میل | G33: 4 | H33: 10.812 | I33: m | J33: 460000 | K33: 4973520 | L33: FEEDER-1000 | M33: Sheet | N33: FALSE
A34: - 1000A - Al - update MTO - rev 00.xlsx | B34: FEEDER-1000 | C34: 33 | D34: ترموفیت | E34: ترموفیت سر و ته باسداکت | F34: 50 | G34: 8 | H34: 0.8 | I34: m | J34: 6823080 | K34: 5458464 | L34: FEEDER-1000 | M34: Sheet | N34: FALSE
A35: - 1000A - Al - update MTO - rev 00.xlsx | B35: FEEDER-1000 | C35: 28 | E35: ساعت کار ( ساعت ) | H35: 6 | I35: h | J35: 13000000 | K35: 78000000 | L35: FEEDER-1000 | M35: Sheet | N35: FALSE
A36: - 1000A - Al - update MTO - rev 00.xlsx | B36: Vertical elbow | C36: 1 | D36: آلومینیوم | E36: پروفیل یو شکل | F36: 0.768 | G36: 2 | H36: 2.1504 | I36: Kg | J36: 8500000 | K36: 18278400 | L36: Vertical elbow | M36: Sheet | N36: FALSE
A37: - 1000A - Al - update MTO - rev 00.xlsx | B37: Vertical elbow | C37: 2 | E37: پروفیل آی شکل | F37: 0 | G37: 0 | H37: 0 | I37: Kg | J37: 8500000 | K37: 0 | L37: Vertical elbow | M37: Sheet | N37: FALSE
A38: - 1000A - Al - update MTO - rev 00.xlsx | B38: Vertical elbow | C38: 3 | E38: هیت سینگ 163 | F38: 0.703 | G38: 2 | H38: 2.3902 | I38: Kg | J38: 8500000 | K38: 20316700 | L38: Vertical elbow | M38: Sheet | N38: FALSE
A39: - 1000A - Al - update MTO - rev 00.xlsx | B39: Vertical elbow | C39: 4 | E39: دایکاست (نگهدارنده کاور) | F39: 120 | G39: 4 | H39: 0.48 | I39: Kg | J39: 8500000 | K39: 4080000 | L39: Vertical elbow | M39: Sheet | N39: FALSE
A40: - 1000A - Al - update MTO - rev 00.xlsx | B40: Vertical elbow | C40: 5 | E40: گارد | F40: 180 | G40: 4 | H40: 0.950616 | I40: Kg | J40: 8500000 | K40: 8080236 | L40: Vertical elbow | M40: Sheet | N40: FALSE
...

Sheet متریال
A1: متریال | B1: قیمت واحد (ریال) | H1: متریال | I1: DIMENTION | J1: UNIT | K1: UNIT PRICE | N1: Source.Name | P1: Name | R1: Line Name
A2: ابعاد بدنه باکس (2000X500) | B2: =VLOOKUP(A:A,H:K,4,1) -> 5200000 | C2: =COUNTIF(H:H,A2) -> 1 | H2: ابعاد بدنه باکس (2000X500) | J2: Kg | K2: 5200000 | N2: - 1000A - Al - update MTO - rev 00.xlsx | P2: Connection protection unit | R2: Line1
A3: ابعاد درپوش (500X500) | B3: =VLOOKUP(A:A,H:K,4,1) -> 0 | C3: =COUNTIF(H:H,A3) -> 1 | H3: ابعاد درپوش (500X500) | J3: Kg | N3: - 1250A - Al - update MTO - rev 00.xlsx | P3: DISTRIBUTION BOARD | R3: Line2
A4: ابعاد ناودانی | B4: =VLOOKUP(A:A,H:K,4,1) -> 0 | C4: =COUNTIF(H:H,A4) -> 1 | H4: ابعاد ناودانی | I4: 300 | J4: 7.86 | N4: - 1600A - Al - update MTO - rev 00.xlsx | P4: FEEDER-1000 | R4: Line3
A5: ابعاد نبشی | B5: =VLOOKUP(A:A,H:K,4,1) -> 0 | C5: =COUNTIF(H:H,A5) -> 1 | H5: ابعاد نبشی | I5: 200 | J5: 7.86 | N5: - 2000A - Al - update MTO - rev 00.xlsx | P5: FEEDER-1250 | R5: Line4
A6: ابکاری پلیت | B6: =VLOOKUP(A:A,H:K,4,1) -> 3000000 | C6: =COUNTIF(H:H,A6) -> 2 | H6: ابکاری پلیت | J6: Kg | K6: 1600000 | N6: - 2500A - Al - update MTO - rev 00.xlsx | P6: FEEDER-1600 | R6: Line5
A7: ابکاری شینه ها سراسر | B7: =VLOOKUP(A:A,H:K,4,1) -> 3600000 | C7: =COUNTIF(H:H,A7) -> 2 | H7: ابکاری پلیت | J7: Kg | K7: 3000000 | N7: - 3200A - Al - update MTO - rev 00.xlsx | P7: FEEDER-1600 1m 4w | R7: Line6
A8: بالبو | B8: =VLOOKUP(A:A,H:K,4,1) -> 11250000 | C8: =COUNTIF(H:H,A8) -> 1 | H8: ابکاری شینه ها سراسر | J8: PCS | K8: 3600000 | N8: - 4000A - Al - update MTO - rev 00.xlsx | P8: FEEDER-1600 1m 5w | R8: Line7
A9: بدنه | B9: =VLOOKUP(A:A,H:K,4,1) -> 5200000 | C9: =COUNTIF(H:H,A9) -> 1 | H9: ابکاری شینه ها سراسر | J9: Kg | K9: 3600000 | N9: - 400A -630A - Al - update MTO - rev 00.xlsx | P9: FEEDER-2000 | R9: Line8
A10: بست برای فیکس کردن بدنه | B10: =VLOOKUP(A:A,H:K,4,1) -> 500000 | C10: =COUNTIF(H:H,A10) -> 1 | H10: بالبو | J10: PCS | K10: 11250000 | N10: - 5000A - Al - update MTO - rev 00.xlsx | P10: FEEDER-2500 | R10: Line9
A11: بولت 12 | B11: =VLOOKUP(A:A,H:K,4,1) -> 100000 | C11: =COUNTIF(H:H,A11) -> 1 | H11: بدنه | J11: Kg | K11: 5200000 | N11: - 800A - Al - update MTO - rev 00.xlsx | P11: FEEDER-3200
A12: پروفیل آی شکل | B12: =VLOOKUP(A:A,H:K,4,1) -> 8500000 | C12: =COUNTIF(H:H,A12) -> 1 | H12: بست برای فیکس کردن بدنه | J12: PCS | K12: 500000 | P12: FEEDER-4000
A13: پروفیل یو شکل | B13: =VLOOKUP(A:A,H:K,4,1) -> 8500000 | C13: =COUNTIF(H:H,A13) -> 1 | H13: بولت 12 | J13: PCS | K13: 100000 | P13: FEEDER-5000
A14: پلیت مونو بلاک | B14: =VLOOKUP(A:A,H:K,4,1) -> 35000000 | C14: =COUNTIF(H:H,A14) -> 1 | H14: پروفیل آی شکل | I14: 2735 | J14: Kg | K14: 8500000 | P14: FEEDER-630
A15: پیچ 10x20 | B15: =VLOOKUP(A:A,H:K,4,1) -> 300000 | C15: =COUNTIF(H:H,A15) -> 1 | H15: پروفیل یو شکل | I15: 2735 | J15: Kg | K15: 8500000 | P15: FEEDER-800
A16: پیچ 12X60 | B16: =VLOOKUP(A:A,H:K,4,1) -> 50000 | C16: =COUNTIF(H:H,A16) -> 1 | H16: پلیت مونو بلاک | I16: 132 | J16: Kg | K16: 35000000 | P16: Flange end
A17: پیچ 6x10 | B17: =VLOOKUP(A:A,H:K,4,1) -> 400000 | C17: =COUNTIF(H:H,A17) -> 1 | H17: پیچ 10x20 | J17: PCS | K17: 300000 | P17: Flexible connection
A18: پیچ 6x15 | B18: =VLOOKUP(A:A,H:K,4,1) -> 400000 | C18: =COUNTIF(H:H,A18) -> 1 | H18: پیچ 12X60 | J18: PCS | K18: 50000 | P18: Horizontal elbow
A19: پیچ 6x20 | B19: =VLOOKUP(A:A,H:K,4,1) -> 10000 | C19: =COUNTIF(H:H,A19) -> 2 | H19: پیچ 6x10 | J19: PCS | K19: 400000 | P19: SPRINH HANGER
A20: پیچ 8x20 | B20: =VLOOKUP(A:A,H:K,4,1) -> 50000 | C20: =COUNTIF(H:H,A20) -> 2 | H20: پیچ 6x15 | J20: PCS | K20: 400000 | P20: Suspension unit ceiling
A21: پیچ 8x25 | B21: =VLOOKUP(A:A,H:K,4,1) -> 200000 | C21: =COUNTIF(H:H,A21) -> 1 | H21: پیچ 6x20 | J21: PCS | K21: 26000 | P21: TOP OFF BOX 250
A22: پیچ 12x120 | B22: =VLOOKUP(A:A,H:K,4,1) -> 2400000 | C22: =COUNTIF(H:H,A22) -> 1 | H22: پیچ 6X20 | J22: PCS | K22: 10000 | P22: Transformer connection
A23: پیچ 6X20 | B23: =VLOOKUP(A:A,H:K,4,1) -> 10000 | C23: =COUNTIF(H:H,A23) -> 1 | H23: پیچ 8x20 | J23: PCS | K23: 200000 | P23: Universal fixing unit
A24: پیچ m10 70 | B24: =VLOOKUP(A:A,H:K,4,1) -> 100000 | C24: =COUNTIF(H:H,A24) -> 1 | H24: پیچ 8x20 | J24: PCS | K24: 50000 | P24: Vertical elbow
A25: پیچ M12 | B25: =VLOOKUP(A:A,H:K,4,1) -> 2000000 | C25: =COUNTIF(H:H,A25) -> 1 | H25: پیچ 8x25 | J25: PCS | K25: 200000
A26: پیچ دو سر رزوه 12 به طول 700 | B26: =VLOOKUP(A:A,H:K,4,1) -> 1200000 | C26: =COUNTIF(H:H,A26) -> 1 | H26: پیچ 12x120 | J26: PCS | K26: 2400000
A27: ترموفیت سر و ته باسداکت | B27: =VLOOKUP(A:A,H:K,4,1) -> 4840000 | C27: =COUNTIF(H:H,A27) -> 6 | H27: پیچ 6X20 | J27: PCS | K27: 10000
A28: جوش اصطکاکی | B28: =VLOOKUP(A:A,H:K,4,1) -> 12000000 | C28: =COUNTIF(H:H,A28) -> 10 | H28: پیچ m10 70 | J28: PCS | K28: 100000
A29: جوشکاری آلومینیوم | B29: =VLOOKUP(A:A,H:K,4,1) -> 30000000 | C29: =COUNTIF(H:H,A29) -> 1 | H29: پیچ M12 | I29: 260 | J29: M | K29: 2000000
A30: چسب سیلیکون | B30: =VLOOKUP(A:A,H:K,4,1) -> 5500000 | C30: =COUNTIF(H:H,A30) -> 1 | H30: پیچ دو سر رزوه 12 به طول 700 | J30: M | K30: 1200000
A31: چسب عایق ها | B31: =VLOOKUP(A:A,H:K,4,1) -> 3600000 | C31: =COUNTIF(H:H,A31) -> 1 | H31: ترموفیت سر و ته باسداکت | I31: 50 | J31: m | K31: 6823080
A32: دایکاست (نگهدارنده کاور) | B32: =VLOOKUP(A:A,H:K,4,1) -> 8500000 | C32: =COUNTIF(H:H,A32) -> 1 | H32: ترموفیت سر و ته باسداکت | I32: 50 | J32: m | K32: 9739400
A33: دستگیره پلاستیکی | B33: =VLOOKUP(A:A,H:K,4,1) -> 0 | C33: =COUNTIF(H:H,A33) -> 1 | H33: ترموفیت سر و ته باسداکت | I33: 50 | J33: m | K33: 12655280
A34: دسته گردان | B34: =VLOOKUP(A:A,H:K,4,1) -> 74000000 | C34: =COUNTIF(H:H,A34) -> 1 | H34: ترموفیت سر و ته باسداکت | I34: 50 | J34: m | K34: 17526080
A35: رنگ پودری | B35: =VLOOKUP(A:A,H:K,4,1) -> 1430000 | C35: =COUNTIF(H:H,A35) -> 2 | H35: ترموفیت سر و ته باسداکت | I35: 50 | J35: m | K35: 3414400
A36: ساعت کار ( ساعت ) | B36: =VLOOKUP(A:A,H:K,4,1) -> 8500000 | C36: =COUNTIF(H:H,A36) -> 2 | H36: ترموفیت سر و ته باسداکت | I36: 50 | J36: m | K36: 4840000
A37: سیم ارت 5 میل | B37: =VLOOKUP(A:A,H:K,4,1) -> 0 | C37: =COUNTIF(H:H,A37) -> 1 | H37: جوش اصطکاکی | K37: 14000000
A38: شینه آلومینیوم 6 میلیمتری | B38: =VLOOKUP(A:A,H:K,4,1) -> 8500000 | C38: =COUNTIF(H:H,A38) -> 1 | H38: جوش اصطکاکی | J38: PCS | K38: 14000000
A39: شینه کشی جهت اتصال باسداکت -به مقدار 70 کیلو | B39: =VLOOKUP(A:A,H:K,4,1) -> 8500000 | C39: =COUNTIF(H:H,A39) -> 1 | H39: جوش اصطکاکی | K39: 18000000
A40: شینه کشی جهت اتصال باسداکت -تا مقدار 70 کیلو | B40: =VLOOKUP(A:A,H:K,4,1) -> 8500000 | C40: =COUNTIF(H:H,A40) -> 1 | H40: جوش اصطکاکی | J40: PCS | K40: 18000000
...

Sheet Line
A1: Source.Name | B1: Line name | C1: Name | D1: Qty | E1: UNIT PRICE | F1: Total Price
A2: - 1000A - Al - update MTO - rev 00.xlsx | B2: Line1 | C2: FEEDER-1000 | D2: 1 | E2: =SUMIFS('Al update MTO - 05-1-30'!K:K,'Al update MTO - 05-1-30'!A:A,A2,'Al update MTO - 05-1-30'!B:B,Line!C2) -> 8.0270004e+08 | F2: =D2*E2 -> 8.0270004e+08
A3: - 1000A - Al - update MTO - rev 00.xlsx | B3: Line1 | C3: Flexible connection | D3: 1 | E3: =SUMIFS('Al update MTO - 05-1-30'!K:K,'Al update MTO - 05-1-30'!A:A,A3,'Al update MTO - 05-1-30'!B:B,Line!C3) -> 125880000 | F3: =D3*E3 -> 125880000
A4: - 1000A - Al - update MTO - rev 00.xlsx | B4: Line1 | C4: TOP OFF BOX 250 | D4: 2 | E4: =SUMIFS('Al update MTO - 05-1-30'!K:K,'Al update MTO - 05-1-30'!A:A,A4,'Al update MTO - 05-1-30'!B:B,Line!C4) -> 220320000 | F4: =D4*E4 -> 440640000
A5: - 1000A - Al - update MTO - rev 00.xlsx | B5: Line1 | C5: Transformer connection | D5: 1 | E5: =SUMIFS('Al update MTO - 05-1-30'!K:K,'Al update MTO - 05-1-30'!A:A,A5,'Al update MTO - 05-1-30'!B:B,Line!C5) -> 138880000 | F5: =D5*E5 -> 138880000
A6: - 1000A - Al - update MTO - rev 00.xlsx | B6: Line2 | C6: FEEDER-1000 | D6: 1 | E6: =SUMIFS('Al update MTO - 05-1-30'!K:K,'Al update MTO - 05-1-30'!A:A,A6,'Al update MTO - 05-1-30'!B:B,Line!C6) -> 8.0270004e+08 | F6: =D6*E6 -> 8.0270004e+08
A7: - 1000A - Al - update MTO - rev 00.xlsx | B7: Line2 | C7: Flexible connection | D7: 1 | E7: =SUMIFS('Al update MTO - 05-1-30'!K:K,'Al update MTO - 05-1-30'!A:A,A7,'Al update MTO - 05-1-30'!B:B,Line!C7) -> 125880000 | F7: =D7*E7 -> 125880000
A8: - 1000A - Al - update MTO - rev 00.xlsx | B8: Line2 | C8: TOP OFF BOX 250 | D8: 2 | E8: =SUMIFS('Al update MTO - 05-1-30'!K:K,'Al update MTO - 05-1-30'!A:A,A8,'Al update MTO - 05-1-30'!B:B,Line!C8) -> 220320000 | F8: =D8*E8 -> 440640000
A9: - 1000A - Al - update MTO - rev 00.xlsx | B9: Line2 | C9: Horizontal elbow | D9: 1 | E9: =SUMIFS('Al update MTO - 05-1-30'!K:K,'Al update MTO - 05-1-30'!A:A,A9,'Al update MTO - 05-1-30'!B:B,Line!C9) -> 4.4633654e+08 | F9: =D9*E9 -> 4.4633654e+08
A10: - 1600A - Al - update MTO - rev 00.xlsx | B10: Line1 | C10: FEEDER-1600 | D10: 1 | E10: =SUMIFS('Al update MTO - 05-1-30'!K:K,'Al update MTO - 05-1-30'!A:A,A10,'Al update MTO - 05-1-30'!B:B,Line!C10) -> 1192956814 | F10: =D10*E10 -> 1192956814
A11: - 1600A - Al - update MTO - rev 00.xlsx | B11: Line1 | C11: Flexible connection | D11: 1 | E11: =SUMIFS('Al update MTO - 05-1-30'!K:K,'Al update MTO - 05-1-30'!A:A,A11,'Al update MTO - 05-1-30'!B:B,Line!C11) -> 195180000 | F11: =D11*E11 -> 195180000
A12: - 1600A - Al - update MTO - rev 00.xlsx | B12: Line1 | C12: TOP OFF BOX 250 | D12: 2 | E12: =SUMIFS('Al update MTO - 05-1-30'!K:K,'Al update MTO - 05-1-30'!A:A,A12,'Al update MTO - 05-1-30'!B:B,Line!C12) -> 220320000 | F12: =D12*E12 -> 440640000
A13: - 1600A - Al - update MTO - rev 00.xlsx | B13: Line1 | C13: Transformer connection | D13: 1 | E13: =SUMIFS('Al update MTO - 05-1-30'!K:K,'Al update MTO - 05-1-30'!A:A,A13,'Al update MTO - 05-1-30'!B:B,Line!C13) -> 187280000 | F13: =D13*E13 -> 187280000
... A17: - 1600A - Al - update MTO - rev 00.xlsx | B17: Line2 | C17: Horizontal elbow | D17: 1 | E17: =SUMIFS('Al update MTO - 05-1-30'!K:K,'Al update MTO - 05-1-30'!A:A,A17,'Al update MTO - 05-1-30'!B:B,Line!C17) -> 5.9762489e+08 | F17: =D17*E17 -> 5.9762489e+08

Sheet خروجی
A3: Row Labels | B3: Sum of Qty | C3: Sum of Total Price
A4: - 1000A - Al - update MTO - rev 00.xlsx | B4: 10 | C4: 3.3236566e+09
A5: Line1 | B5: 5 | C5: 1.5081e+09
A6: Line2 | B6: 5 | C6: 1.8155566e+09
A7: - 1600A - Al - update MTO - rev 00.xlsx | B7: 10 | C7: 4.4424585e+09
A8: Line1 | B8: 5 | C8: 2016056814
A9: Line2 | B9: 5 | C9: 2.4264017e+09
A10: Grand Total | B10: 20 | C10: 7.7661151e+09
